[2025-07-09T09:13:34.583+0000] {taskinstance.py:1159} INFO - Dependencies all met for dep_context=non-requeueable deps ti=<TaskInstance: ecommerce_etl_pipeline.extract_transform_sales scheduled__2025-07-09T09:10:29.896960+00:00 [queued]>
[2025-07-09T09:13:34.588+0000] {taskinstance.py:1159} INFO - Dependencies all met for dep_context=requeueable deps ti=<TaskInstance: ecommerce_etl_pipeline.extract_transform_sales scheduled__2025-07-09T09:10:29.896960+00:00 [queued]>
[2025-07-09T09:13:34.588+0000] {taskinstance.py:1361} INFO - Starting attempt 1 of 4
[2025-07-09T09:13:34.595+0000] {taskinstance.py:1382} INFO - Executing <Task(PythonOperator): extract_transform_sales> on 2025-07-09 09:10:29.896960+00:00
[2025-07-09T09:13:34.598+0000] {standard_task_runner.py:57} INFO - Started process 379 to run task
[2025-07-09T09:13:34.601+0000] {standard_task_runner.py:84} INFO - Running: ['***', 'tasks', 'run', 'ecommerce_etl_pipeline', 'extract_transform_sales', 'scheduled__2025-07-09T09:10:29.896960+00:00', '--job-id', '31', '--raw', '--subdir', 'DAGS_FOLDER/ecommerce_etl_dag.py', '--cfg-path', '/tmp/tmp9cj_ghs3']
[2025-07-09T09:13:34.604+0000] {standard_task_runner.py:85} INFO - Job 31: Subtask extract_transform_sales
[2025-07-09T09:13:34.779+0000] {task_command.py:415} INFO - Running <TaskInstance: ecommerce_etl_pipeline.extract_transform_sales scheduled__2025-07-09T09:10:29.896960+00:00 [running]> on host fc060bb3c09b
[2025-07-09T09:13:34.867+0000] {taskinstance.py:1660} INFO - Exporting env vars: AIRFLOW_CTX_DAG_OWNER='data_team' AIRFLOW_CTX_DAG_ID='ecommerce_etl_pipeline' AIRFLOW_CTX_TASK_ID='extract_transform_sales' AIRFLOW_CTX_EXECUTION_DATE='2025-07-09T09:10:29.896960+00:00' AIRFLOW_CTX_TRY_NUMBER='1' AIRFLOW_CTX_DAG_RUN_ID='scheduled__2025-07-09T09:10:29.896960+00:00'
[2025-07-09T09:13:34.868+0000] {ecommerce_etl_dag.py:151} INFO - Bắt đầu extract sales data...
[2025-07-09T09:13:34.875+0000] {base.py:73} INFO - Using connection ID 'postgres_data' for task execution.
[2025-07-09T09:13:34.880+0000] {sql.py:418} INFO - Running statement: TRUNCATE TABLE target_data.fact_sales CASCADE;, parameters: None
[2025-07-09T09:13:34.894+0000] {base.py:73} INFO - Using connection ID 'postgres_data' for task execution.
[2025-07-09T09:13:34.909+0000] {logging_mixin.py:151} WARNING - /home/***/.local/lib/python3.9/site-packages/***/providers/common/sql/hooks/sql.py:219 UserWarning: pandas only supports SQLAlchemy connectable (engine/connection) or database string URI or sqlite3 DBAPI2 connection. Other DBAPI2 objects are not tested. Please consider using SQLAlchemy.
[2025-07-09T09:13:34.913+0000] {ecommerce_etl_dag.py:177} INFO - Extracted 7 sales records
[2025-07-09T09:13:34.924+0000] {base.py:73} INFO - Using connection ID 'postgres_data' for task execution.
[2025-07-09T09:13:34.940+0000] {ecommerce_etl_dag.py:201} ERROR - Lỗi trong extract_and_transform_sales: insert or update on table "fact_sales" violates foreign key constraint "fact_sales_customer_key_fkey"
DETAIL:  Key (customer_key)=(1) is not present in table "dim_customers".

[2025-07-09T09:13:34.941+0000] {taskinstance.py:1943} ERROR - Task failed with exception
Traceback (most recent call last):
  File "/home/airflow/.local/lib/python3.9/site-packages/airflow/operators/python.py", line 192, in execute
    return_value = self.execute_callable()
  File "/home/airflow/.local/lib/python3.9/site-packages/airflow/operators/python.py", line 209, in execute_callable
    return self.python_callable(*self.op_args, **self.op_kwargs)
  File "/opt/airflow/dags/ecommerce_etl_dag.py", line 192, in extract_and_transform_sales
    execute_values(cur, insert_query, data_tuples)
  File "/home/airflow/.local/lib/python3.9/site-packages/psycopg2/extras.py", line 1299, in execute_values
    cur.execute(b''.join(parts))
psycopg2.errors.ForeignKeyViolation: insert or update on table "fact_sales" violates foreign key constraint "fact_sales_customer_key_fkey"
DETAIL:  Key (customer_key)=(1) is not present in table "dim_customers".

[2025-07-09T09:13:34.970+0000] {taskinstance.py:1400} INFO - Marking task as UP_FOR_RETRY. dag_id=ecommerce_etl_pipeline, task_id=extract_transform_sales, execution_date=20250709T091029, start_date=20250709T091334, end_date=20250709T091334
[2025-07-09T09:13:34.996+0000] {standard_task_runner.py:104} ERROR - Failed to execute job 31 for task extract_transform_sales (insert or update on table "fact_sales" violates foreign key constraint "fact_sales_customer_key_fkey"
DETAIL:  Key (customer_key)=(1) is not present in table "dim_customers".
; 379)
[2025-07-09T09:13:35.032+0000] {local_task_job_runner.py:228} INFO - Task exited with return code 1
[2025-07-09T09:13:35.190+0000] {taskinstance.py:2784} INFO - 0 downstream tasks scheduled from follow-on schedule check
