[2025-07-09T09:00:10.230+0000] {taskinstance.py:1159} INFO - Dependencies all met for dep_context=non-requeueable deps ti=<TaskInstance: ecommerce_etl_pipeline.extract_transform_customers scheduled__2025-07-09T09:00:08+00:00 [queued]>
[2025-07-09T09:00:10.239+0000] {taskinstance.py:1159} INFO - Dependencies all met for dep_context=requeueable deps ti=<TaskInstance: ecommerce_etl_pipeline.extract_transform_customers scheduled__2025-07-09T09:00:08+00:00 [queued]>
[2025-07-09T09:00:10.241+0000] {taskinstance.py:1361} INFO - Starting attempt 1 of 2
[2025-07-09T09:00:10.252+0000] {taskinstance.py:1382} INFO - Executing <Task(PythonOperator): extract_transform_customers> on 2025-07-09 09:00:08+00:00
[2025-07-09T09:00:10.257+0000] {standard_task_runner.py:57} INFO - Started process 589 to run task
[2025-07-09T09:00:10.261+0000] {standard_task_runner.py:84} INFO - Running: ['***', 'tasks', 'run', 'ecommerce_etl_pipeline', 'extract_transform_customers', 'scheduled__2025-07-09T09:00:08+00:00', '--job-id', '67', '--raw', '--subdir', 'DAGS_FOLDER/ecommerce_etl_dag.py', '--cfg-path', '/tmp/tmpb19xe_93']
[2025-07-09T09:00:10.264+0000] {standard_task_runner.py:85} INFO - Job 67: Subtask extract_transform_customers
[2025-07-09T09:00:10.471+0000] {task_command.py:415} INFO - Running <TaskInstance: ecommerce_etl_pipeline.extract_transform_customers scheduled__2025-07-09T09:00:08+00:00 [running]> on host a30f004cea1f
[2025-07-09T09:00:10.535+0000] {taskinstance.py:1660} INFO - Exporting env vars: AIRFLOW_CTX_DAG_OWNER='data_team' AIRFLOW_CTX_DAG_ID='ecommerce_etl_pipeline' AIRFLOW_CTX_TASK_ID='extract_transform_customers' AIRFLOW_CTX_EXECUTION_DATE='2025-07-09T09:00:08+00:00' AIRFLOW_CTX_TRY_NUMBER='1' AIRFLOW_CTX_DAG_RUN_ID='scheduled__2025-07-09T09:00:08+00:00'
[2025-07-09T09:00:10.536+0000] {ecommerce_etl_dag.py:32} INFO - Bắt đầu extract customers data...
[2025-07-09T09:00:10.551+0000] {taskinstance.py:1943} ERROR - Task failed with exception
Traceback (most recent call last):
  File "/home/airflow/.local/lib/python3.9/site-packages/airflow/operators/python.py", line 192, in execute
    return_value = self.execute_callable()
  File "/home/airflow/.local/lib/python3.9/site-packages/airflow/operators/python.py", line 209, in execute_callable
    return self.python_callable(*self.op_args, **self.op_kwargs)
  File "/opt/airflow/dags/ecommerce_etl_dag.py", line 54, in extract_and_transform_customers
    df = postgres_hook.get_pandas_df(extract_query)
  File "/home/airflow/.local/lib/python3.9/site-packages/airflow/providers/common/sql/hooks/sql.py", line 218, in get_pandas_df
    with closing(self.get_conn()) as conn:
  File "/home/airflow/.local/lib/python3.9/site-packages/airflow/providers/postgres/hooks/postgres.py", line 124, in get_conn
    conn = deepcopy(self.connection or self.get_connection(conn_id))
  File "/home/airflow/.local/lib/python3.9/site-packages/airflow/hooks/base.py", line 72, in get_connection
    conn = Connection.get_connection_from_secrets(conn_id)
  File "/home/airflow/.local/lib/python3.9/site-packages/airflow/models/connection.py", line 477, in get_connection_from_secrets
    raise AirflowNotFoundException(f"The conn_id `{conn_id}` isn't defined")
airflow.exceptions.AirflowNotFoundException: The conn_id `postgres_data` isn't defined
[2025-07-09T09:00:10.556+0000] {taskinstance.py:1400} INFO - Marking task as UP_FOR_RETRY. dag_id=ecommerce_etl_pipeline, task_id=extract_transform_customers, execution_date=20250709T090008, start_date=20250709T090010, end_date=20250709T090010
[2025-07-09T09:00:10.570+0000] {standard_task_runner.py:104} ERROR - Failed to execute job 67 for task extract_transform_customers (The conn_id `postgres_data` isn't defined; 589)
[2025-07-09T09:00:10.604+0000] {local_task_job_runner.py:228} INFO - Task exited with return code 1
[2025-07-09T09:00:10.856+0000] {taskinstance.py:2784} INFO - 0 downstream tasks scheduled from follow-on schedule check
