[2025-07-09T08:28:56.757+0000] {taskinstance.py:1159} INFO - Dependencies all met for dep_context=non-requeueable deps ti=<TaskInstance: ecommerce_etl_pipeline.extract_transform_products manual__2025-07-09T08:28:55+00:00 [queued]>
[2025-07-09T08:28:56.765+0000] {taskinstance.py:1159} INFO - Dependencies all met for dep_context=requeueable deps ti=<TaskInstance: ecommerce_etl_pipeline.extract_transform_products manual__2025-07-09T08:28:55+00:00 [queued]>
[2025-07-09T08:28:56.766+0000] {taskinstance.py:1361} INFO - Starting attempt 1 of 2
[2025-07-09T08:28:56.777+0000] {taskinstance.py:1382} INFO - Executing <Task(PythonOperator): extract_transform_products> on 2025-07-09 08:28:55+00:00
[2025-07-09T08:28:56.782+0000] {standard_task_runner.py:57} INFO - Started process 344 to run task
[2025-07-09T08:28:56.788+0000] {standard_task_runner.py:84} INFO - Running: ['***', 'tasks', 'run', 'ecommerce_etl_pipeline', 'extract_transform_products', 'manual__2025-07-09T08:28:55+00:00', '--job-id', '5', '--raw', '--subdir', 'DAGS_FOLDER/ecommerce_etl_dag.py', '--cfg-path', '/tmp/tmpbedxf7et']
[2025-07-09T08:28:56.791+0000] {standard_task_runner.py:85} INFO - Job 5: Subtask extract_transform_products
[2025-07-09T08:28:57.043+0000] {task_command.py:415} INFO - Running <TaskInstance: ecommerce_etl_pipeline.extract_transform_products manual__2025-07-09T08:28:55+00:00 [running]> on host 369b738e5f2d
[2025-07-09T08:28:57.097+0000] {taskinstance.py:1660} INFO - Exporting env vars: AIRFLOW_CTX_DAG_OWNER='data_team' AIRFLOW_CTX_DAG_ID='ecommerce_etl_pipeline' AIRFLOW_CTX_TASK_ID='extract_transform_products' AIRFLOW_CTX_EXECUTION_DATE='2025-07-09T08:28:55+00:00' AIRFLOW_CTX_TRY_NUMBER='1' AIRFLOW_CTX_DAG_RUN_ID='manual__2025-07-09T08:28:55+00:00'
[2025-07-09T08:28:57.099+0000] {ecommerce_etl_dag.py:72} INFO - Bắt đầu extract products data...
[2025-07-09T08:28:57.107+0000] {base.py:73} INFO - Using connection ID 'postgres_data' for task execution.
[2025-07-09T08:28:57.132+0000] {logging_mixin.py:151} WARNING - /home/***/.local/lib/python3.9/site-packages/***/providers/common/sql/hooks/sql.py:219 UserWarning: pandas only supports SQLAlchemy connectable (engine/connection) or database string URI or sqlite3 DBAPI2 connection. Other DBAPI2 objects are not tested. Please consider using SQLAlchemy.
[2025-07-09T08:28:57.134+0000] {taskinstance.py:1943} ERROR - Task failed with exception
Traceback (most recent call last):
  File "/home/airflow/.local/lib/python3.9/site-packages/pandas/io/sql.py", line 2202, in execute
    cur.execute(sql, *args)
psycopg2.errors.UndefinedTable: relation "source_data.products" does not exist
LINE 18:     FROM source_data.products
                  ^


The above exception was the direct cause of the following exception:

Traceback (most recent call last):
  File "/home/airflow/.local/lib/python3.9/site-packages/airflow/operators/python.py", line 192, in execute
    return_value = self.execute_callable()
  File "/home/airflow/.local/lib/python3.9/site-packages/airflow/operators/python.py", line 209, in execute_callable
    return self.python_callable(*self.op_args, **self.op_kwargs)
  File "/opt/airflow/dags/ecommerce_etl_dag.py", line 96, in extract_and_transform_products
    df = postgres_hook.get_pandas_df(extract_query)
  File "/home/airflow/.local/lib/python3.9/site-packages/airflow/providers/common/sql/hooks/sql.py", line 219, in get_pandas_df
    return psql.read_sql(sql, con=conn, params=parameters, **kwargs)
  File "/home/airflow/.local/lib/python3.9/site-packages/pandas/io/sql.py", line 635, in read_sql
    return pandas_sql.read_query(
  File "/home/airflow/.local/lib/python3.9/site-packages/pandas/io/sql.py", line 2266, in read_query
    cursor = self.execute(sql, params)
  File "/home/airflow/.local/lib/python3.9/site-packages/pandas/io/sql.py", line 2214, in execute
    raise ex from exc
pandas.errors.DatabaseError: Execution failed on sql '
    SELECT 
        product_id,
        product_name,
        category,
        price,
        CASE 
            WHEN price >= 500 THEN 'Premium'
            WHEN price >= 100 THEN 'Standard'
            ELSE 'Budget'
        END as price_tier,
        CASE 
            WHEN stock_quantity >= 100 THEN 'In Stock'
            WHEN stock_quantity >= 10 THEN 'Low Stock'
            ELSE 'Out of Stock'
        END as stock_status,
        supplier
    FROM source_data.products
    ': relation "source_data.products" does not exist
LINE 18:     FROM source_data.products
                  ^

[2025-07-09T08:28:57.144+0000] {taskinstance.py:1400} INFO - Marking task as UP_FOR_RETRY. dag_id=ecommerce_etl_pipeline, task_id=extract_transform_products, execution_date=20250709T082855, start_date=20250709T082856, end_date=20250709T082857
[2025-07-09T08:28:57.154+0000] {standard_task_runner.py:104} ERROR - Failed to execute job 5 for task extract_transform_products (Execution failed on sql '
    SELECT 
        product_id,
        product_name,
        category,
        price,
        CASE 
            WHEN price >= 500 THEN 'Premium'
            WHEN price >= 100 THEN 'Standard'
            ELSE 'Budget'
        END as price_tier,
        CASE 
            WHEN stock_quantity >= 100 THEN 'In Stock'
            WHEN stock_quantity >= 10 THEN 'Low Stock'
            ELSE 'Out of Stock'
        END as stock_status,
        supplier
    FROM source_data.products
    ': relation "source_data.products" does not exist
LINE 18:     FROM source_data.products
                  ^
; 344)
[2025-07-09T08:28:57.174+0000] {local_task_job_runner.py:228} INFO - Task exited with return code 1
[2025-07-09T08:28:57.588+0000] {taskinstance.py:2784} INFO - 0 downstream tasks scheduled from follow-on schedule check
