[2025-07-09T09:05:12.111+0000] {taskinstance.py:1159} INFO - Dependencies all met for dep_context=non-requeueable deps ti=<TaskInstance: ecommerce_etl_pipeline.extract_transform_products scheduled__2025-07-09T09:00:08+00:00 [queued]>
[2025-07-09T09:05:12.117+0000] {taskinstance.py:1159} INFO - Dependencies all met for dep_context=requeueable deps ti=<TaskInstance: ecommerce_etl_pipeline.extract_transform_products scheduled__2025-07-09T09:00:08+00:00 [queued]>
[2025-07-09T09:05:12.118+0000] {taskinstance.py:1361} INFO - Starting attempt 2 of 2
[2025-07-09T09:05:12.127+0000] {taskinstance.py:1382} INFO - Executing <Task(PythonOperator): extract_transform_products> on 2025-07-09 09:00:08+00:00
[2025-07-09T09:05:12.130+0000] {standard_task_runner.py:57} INFO - Started process 868 to run task
[2025-07-09T09:05:12.132+0000] {standard_task_runner.py:84} INFO - Running: ['***', 'tasks', 'run', 'ecommerce_etl_pipeline', 'extract_transform_products', 'scheduled__2025-07-09T09:00:08+00:00', '--job-id', '118', '--raw', '--subdir', 'DAGS_FOLDER/ecommerce_etl_dag.py', '--cfg-path', '/tmp/tmpog7lykhe']
[2025-07-09T09:05:12.133+0000] {standard_task_runner.py:85} INFO - Job 118: Subtask extract_transform_products
[2025-07-09T09:05:12.270+0000] {task_command.py:415} INFO - Running <TaskInstance: ecommerce_etl_pipeline.extract_transform_products scheduled__2025-07-09T09:00:08+00:00 [running]> on host a30f004cea1f
[2025-07-09T09:05:12.306+0000] {taskinstance.py:1660} INFO - Exporting env vars: AIRFLOW_CTX_DAG_OWNER='data_team' AIRFLOW_CTX_DAG_ID='ecommerce_etl_pipeline' AIRFLOW_CTX_TASK_ID='extract_transform_products' AIRFLOW_CTX_EXECUTION_DATE='2025-07-09T09:00:08+00:00' AIRFLOW_CTX_TRY_NUMBER='2' AIRFLOW_CTX_DAG_RUN_ID='scheduled__2025-07-09T09:00:08+00:00'
[2025-07-09T09:05:12.307+0000] {ecommerce_etl_dag.py:72} INFO - Bắt đầu extract products data...
[2025-07-09T09:05:12.315+0000] {taskinstance.py:1943} ERROR - Task failed with exception
Traceback (most recent call last):
  File "/home/airflow/.local/lib/python3.9/site-packages/airflow/operators/python.py", line 192, in execute
    return_value = self.execute_callable()
  File "/home/airflow/.local/lib/python3.9/site-packages/airflow/operators/python.py", line 209, in execute_callable
    return self.python_callable(*self.op_args, **self.op_kwargs)
  File "/opt/airflow/dags/ecommerce_etl_dag.py", line 96, in extract_and_transform_products
    df = postgres_hook.get_pandas_df(extract_query)
  File "/home/airflow/.local/lib/python3.9/site-packages/airflow/providers/common/sql/hooks/sql.py", line 218, in get_pandas_df
    with closing(self.get_conn()) as conn:
  File "/home/airflow/.local/lib/python3.9/site-packages/airflow/providers/postgres/hooks/postgres.py", line 124, in get_conn
    conn = deepcopy(self.connection or self.get_connection(conn_id))
  File "/home/airflow/.local/lib/python3.9/site-packages/airflow/hooks/base.py", line 72, in get_connection
    conn = Connection.get_connection_from_secrets(conn_id)
  File "/home/airflow/.local/lib/python3.9/site-packages/airflow/models/connection.py", line 477, in get_connection_from_secrets
    raise AirflowNotFoundException(f"The conn_id `{conn_id}` isn't defined")
airflow.exceptions.AirflowNotFoundException: The conn_id `postgres_data` isn't defined
[2025-07-09T09:05:12.318+0000] {taskinstance.py:1400} INFO - Marking task as FAILED. dag_id=ecommerce_etl_pipeline, task_id=extract_transform_products, execution_date=20250709T090008, start_date=20250709T090512, end_date=20250709T090512
[2025-07-09T09:05:12.323+0000] {standard_task_runner.py:104} ERROR - Failed to execute job 118 for task extract_transform_products (The conn_id `postgres_data` isn't defined; 868)
[2025-07-09T09:05:12.361+0000] {local_task_job_runner.py:228} INFO - Task exited with return code 1
[2025-07-09T09:05:12.446+0000] {taskinstance.py:2784} INFO - 0 downstream tasks scheduled from follow-on schedule check
